Workbook

Sheet INPUT
A1: BARRETT PLUMBING INC. — COMMERCIAL ESTIMATE INPUT
A2: Complete all blue cells. Yellow cells require attention before submitting.
A4: PROJECT INFORMATION | D4: CREW & SCHEDULE
A5: Project Name | B5: Community Park | D5: Crew Size (# of plumbers) | E5: 2
A6: Client / GC Name | D6: Estimated Job Duration (days)
A7: Project Address | D7: Shift Length (hours/day) | E7: 8
A8: City / Municipality | D8: Master Plumber on Job? (Y/N) | E8: Y
A9: Estimator Name | B9: Vance | D9: Apprentice on Job? (Y/N) | E9: Y
A10: Estimate Date | D10: Job Complexity | E10: Normal
A11: Bid Due Date | D11: PIPE MATERIAL SELECTIONS
A12: Project Number / RFQ # | D12: Water Supply Pipe Material | E12: Type L Copper
D13: DWV Pipe Material | E13: Schedule 40 PVC
A14: BUILDING INFORMATION | D14: Compressed Air Pipe Material | E14: Black Iron
A15: Building Type | B15: Restroom Building
A16: Number of Floors | B16: 1 | D16: NOTES / SPECIAL CONDITIONS
A17: Total Square Footage | B17: 754
A18: Wall Construction Type | B18: CMU Block
A19: Slab on Grade? (Y/N) | B19: Y
A20: Below-Grade Work Required? (Y/N) | B20: Y
A22: SCOPE FLAGS — CHECK ALL THAT APPLY (Y/N)
A23: Excavation Needed | B23: N
A24: Grease Interceptor / Sand Separator | B24: N
A25: Backflow Preventer / RPZ Required | B25: N
A26: Pressure Reducing Valve (PRV) Station | B26: N
A27: Compressed Air System in Scope | B27: N
A28: Water Heater / Booster Required | B28: N
A29: Floor Drain System Required | B29: Y
A30: Roof Drain / Storm System in Scope | B30: N
A31: Medical Gas in Scope | B31: N
A32: Fire Suppression Coordination Required | B32: N
A33: Insulation by Barrett (not sub) | B33: Y
A34: Concrete Cutting Required | B34: N
... A36: Masonry Sleeve Coordination Required | B36: N

Sheet DEMO ESTIMATE
A1: BARRETT PLUMBING INC. — PLUMBING DEMOLITION ESTIMATE
A2: Standalone tab — use independently or roll total into Summary. Customer/GC handles pipe disposal. Labor rates pull from SETTINGS.
A4: PROJECT / REFERENCE | C4: DATE | J4: DEMO LABOR RATE REFERENCE
J5: Yellow cells = adjustable defaults. Conservative = use underground rate for all locations.
J6: Location | K6: Typical Hrs/LF
A7: Pipe Material / Size | B7: Underground Demo LF | C7: In-Wall Demo LF | D7: Ceiling / Rafter Demo LF | E7: TOTAL LF | F7: Demo Hrs/LF (from table →) | G7: TOTAL Demo Hrs | H7: Labor Cost ($) | J7: ── CAST IRON NO-HUB ──
A8: ── CAST IRON NO-HUB | J8: Underground (slab cut required) | K8: 0.06 – 0.08
A9: 4" Cast Iron No-Hub | B9: 0 | C9: 0 | D9: 0 | E9: =B9+C9+D9 | F9: 0.07 | G9: =E9*F9*SETTINGS!$B$17 | H9: =G9*SETTINGS!B11 | J9: In-Wall (open wall required) | K9: 0.04 – 0.06
A10: 3" Cast Iron No-Hub | B10: 0 | C10: 0 | D10: 0 | E10: =B10+C10+D10 | F10: 0.06 | G10: =E10*F10*SETTINGS!$B$17 | H10: =G10*SETTINGS!B11 | J10: Ceiling / Rafter Hung | K10: 0.03 – 0.05
A11: 2" Cast Iron No-Hub | B11: 0 | C11: 0 | D11: 0 | E11: =B11+C11+D11 | F11: 0.05 | G11: =E11*F11*SETTINGS!$B$17 | H11: =G11*SETTINGS!B11 | J11: ── SCHEDULE 40 PVC ──
A12: 1-1/2" Cast Iron No-Hub | B12: 0 | C12: 0 | D12: 0 | E12: =B12+C12+D12 | F12: 0.04 | G12: =E12*F12*SETTINGS!$B$17 | H12: =G12*SETTINGS!B11 | J12: Underground | K12: 0.04 – 0.05
A13: CAST IRON NO-HUB SUBTOTAL | E13: =SUM(E9:E12) | G13: =SUM(G9:G12) | H13: =SUM(H9:H12) | J13: In-Wall | K13: 0.03 – 0.04
A14: ── SCHEDULE 40 PVC | J14: Ceiling / Rafter Hung | K14: 0.02 – 0.03
A15: 4" Schedule 40 PVC | B15: 0 | C15: 0 | D15: 0 | E15: =B15+C15+D15 | F15: 0.05 | G15: =E15*F15*SETTINGS!$B$17 | H15: =G15*SETTINGS!B11 | J15: ── COPPER ──
A16: 3" Schedule 40 PVC | B16: 0 | C16: 0 | D16: 0 | E16: =B16+C16+D16 | F16: 0.04 | G16: =E16*F16*SETTINGS!$B$17 | H16: =G16*SETTINGS!B11 | J16: Underground | K16: 0.06 – 0.08
A17: 2" Schedule 40 PVC | B17: 0 | C17: 0 | D17: 0 | E17: =B17+C17+D17 | F17: 0.03 | G17: =E17*F17*SETTINGS!$B$17 | H17: =G17*SETTINGS!B11 | J17: In-Wall | K17: 0.05 – 0.07
A18: 1-1/2" Schedule 40 PVC | B18: 0 | C18: 0 | D18: 0 | E18: =B18+C18+D18 | F18: 0.03 | G18: =E18*F18*SETTINGS!$B$17 | H18: =G18*SETTINGS!B11 | J18: Ceiling / Rafter Hung | K18: 0.03 – 0.05
A19: 1-1/4" Schedule 40 PVC | B19: 0 | C19: 0 | D19: 0 | E19: =B19+C19+D19 | F19: 0.03 | G19: =E19*F19*SETTINGS!$B$17 | H19: =G19*SETTINGS!B11 | J19: ── BLACK IRON (Threaded) ──
A20: SCHEDULE 40 PVC SUBTOTAL | E20: =SUM(E15:E19) | G20: =SUM(G15:G19) | H20: =SUM(H15:H19) | J20: Underground | K20: 0.10 – 0.12
A21: ── COPPER (Type L or K) | J21: In-Wall | K21: 0.08 – 0.10
A22: 2" Copper | B22: 0 | C22: 0 | D22: 0 | E22: =B22+C22+D22 | F22: 0.08 | G22: =E22*F22*SETTINGS!$B$17 | H22: =G22*SETTINGS!B11 | J22: Ceiling / Rafter Hung | K22: 0.06 – 0.08
A23: 1-1/2" Copper | B23: 0 | C23: 0 | D23: 0 | E23: =B23+C23+D23 | F23: 0.07 | G23: =E23*F23*SETTINGS!$B$17 | H23: =G23*SETTINGS!B11
A24: 1-1/4" Copper | B24: 0 | C24: 0 | D24: 0 | E24: =B24+C24+D24 | F24: 0.06 | G24: =E24*F24*SETTINGS!$B$17 | H24: =G24*SETTINGS!B11 | J24: NOTE: Underground rates include
A25: 1" Copper | B25: 0 | C25: 0 | D25: 0 | E25: =B25+C25+D25 | F25: 0.05 | G25: =E25*F25*SETTINGS!$B$17 | H25: =G25*SETTINGS!B11 | J25: slab saw-cut + excavation time.
A26: 3/4" Copper | B26: 0 | C26: 0 | D26: 0 | E26: =B26+C26+D26 | F26: 0.05 | G26: =E26*F26*SETTINGS!$B$17 | H26: =G26*SETTINGS!B11 | J26: Add 15-20% if slab > 4" thick.
A27: 1/2" Copper | B27: 0 | C27: 0 | D27: 0 | E27: =B27+C27+D27 | F27: 0.04 | G27: =E27*F27*SETTINGS!$B$17 | H27: =G27*SETTINGS!B11
A28: COPPER (Type L or K) SUBTOTAL | E28: =SUM(E22:E27) | G28: =SUM(G22:G27) | H28: =SUM(H22:H27) | J28: ── FIXTURE DEMO NOTES ──
A29: ── BLACK IRON — THREADED | J29: Flush-valve WC / Urinal: faster
A30: 2" Black Iron | B30: 0 | C30: 0 | D30: 0 | E30: =B30+C30+D30 | F30: 0.12 | G30: =E30*F30*SETTINGS!$B$17 | H30: =G30*SETTINGS!B11 | J30: than tank type — less hardware.
A31: 1-1/2" Black Iron | B31: 0 | C31: 0 | D31: 0 | E31: =B31+C31+D31 | F31: 0.1 | G31: =E31*F31*SETTINGS!$B$17 | H31: =G31*SETTINGS!B11 | J31: Cap/Stub flag adds capping hrs
A32: 1" Black Iron | B32: 0 | C32: 0 | D32: 0 | E32: =B32+C32+D32 | F32: 0.09 | G32: =E32*F32*SETTINGS!$B$17 | H32: =G32*SETTINGS!B11 | J32: per rough-in opening left open.
A33: 3/4" Black Iron | B33: 0 | C33: 0 | D33: 0 | E33: =B33+C33+D33 | F33: 0.08 | G33: =E33*F33*SETTINGS!$B$17 | H33: =G33*SETTINGS!B11 | J33: Exterior grease trap demo
A34: 1/2" Black Iron | B34: 0 | C34: 0 | D34: 0 | E34: =B34+C34+D34 | F34: 0.07 | G34: =E34*F34*SETTINGS!$B$17 | H34: =G34*SETTINGS!B11 | J34: assumes excavation by others.
A35: BLACK IRON — THREADED SUBTOTAL | E35: =SUM(E30:E34) | G35: =SUM(G30:G34) | H35: =SUM(H30:H34)
A37: PIPE DEMO TOTAL — ALL SYSTEMS | E37: =E13+E20+E28+E35 | G37: =G13+G20+G28+G35 | H37: =H13+H20+H28+H35
A39: FIXTURE DEMOLITION
A40: Fixture Type | B40: Qty to Remove | C40: Demo Hrs Each (from table →) | D40: TOTAL Demo Hrs | E40: Labor Cost ($) | F40: Cap / Stub Req'd? | G40: Cap/Stub Hrs Add. | H40: TOTAL FIXTURE COST ($)
A41: ── RESTROOM FIXTURES ──
A42: Water Closet (floor-mounted) | B42: 0 | C42: 1.25 | D42: =B42*(C42+IF(F42="Y",G42,0))*SETTINGS!$B$17 | E42: =D42*SETTINGS!B11 | F42: N | G42: 0.5 | H42: =E42
A43: Water Closet (wall-hung) | B43: 0 | C43: 1.75 | D43: =B43*(C43+IF(F43="Y",G43,0))*SETTINGS!$B$17 | E43: =D43*SETTINGS!B11 | F43: N | G43: 0.75 | H43: =E43
...

Sheet FIXTURE SCHEDULE
A1: BARRETT PLUMBING INC. — FIXTURE & SYSTEM SCHEDULE
A2: Enter fixture counts by floor. Fixture units (FU) auto-calculated per Michigan Plumbing Code Table 709.1
A4: Fixture Type | B4: Floor 1 | C4: Floor 2 | D4: Floor 3 | E4: Floor 4 | F4: Floor 5 | G4: TOTAL QTY | H4: FU Each | I4: TOTAL FU
A5: ── RESTROOM FIXTURES ──
A6: Water Closet (Flush Valve) | B6: 6 | C6: 0 | D6: 0 | E6: 0 | F6: 0 | G6: =SUM(B6:F6) | H6: 4 | I6: =G6*H6
A7: Water Closet (Tank Type) | B7: 0 | E7: 0 | F7: 0 | G7: =SUM(B7:F7) | H7: 3 | I7: =G7*H7
A8: Urinal (Flush Valve) | B8: 0 | E8: 0 | F8: 0 | G8: =SUM(B8:F8) | H8: 4 | I8: =G8*H8
A9: Lavatory (Single) | B9: 6 | E9: 0 | F9: 0 | G9: =SUM(B9:F9) | H9: 1 | I9: =G9*H9
A10: Lavatory (Multiple / Group) | B10: 0 | E10: 0 | F10: 0 | G10: =SUM(B10:F10) | H10: 2 | I10: =G10*H10
A11: ── KITCHEN / FOOD SERVICE ──
A12: 3-Compartment Sink | B12: 0 | C12: 0 | D12: 0 | E12: 0 | F12: 0 | G12: =SUM(B12:F12) | H12: 3 | I12: =G12*H12
A13: Prep Sink / Hand Sink | B13: 0 | C13: 0 | D13: 0 | E13: 0 | F13: 0 | G13: =SUM(B13:F13) | H13: 1 | I13: =G13*H13
A14: Kitchen Sink (Double Basin) | B14: 0 | E14: 0 | F14: 0 | G14: =SUM(B14:F14) | H14: 2 | I14: =G14*H14
A15: Kitchen Sink (Single Basin) | B15: 0 | E15: 0 | F15: 0 | G15: =SUM(B15:F15) | H15: 2 | I15: =G15*H15
A16: Commercial Dishwasher | B16: 0 | E16: 0 | F16: 0 | G16: =SUM(B16:F16) | H16: 4 | I16: =G16*H16
A17: Ice Maker Connection | B17: 0 | E17: 0 | F17: 0 | G17: =SUM(B17:F17) | H17: 1 | I17: =G17*H17
A18: ── UTILITY / SPECIALTY ──
A19: Mop Sink / Service Sink | B19: 1 | E19: 0 | F19: 0 | G19: =SUM(B19:F19) | H19: 3 | I19: =G19*H19
A20: Floor Drain (2") | B20: 0 | E20: 0 | F20: 0 | G20: =SUM(B20:F20) | H20: 1 | I20: =G20*H20
A21: Floor Drain (3") | B21: 0 | E21: 0 | F21: 0 | G21: =SUM(B21:F21) | H21: 2 | I21: =G21*H21
A22: Floor Drain (4") | B22: 9 | E22: 0 | F22: 0 | G22: =SUM(B22:F22) | H22: 3 | I22: =G22*H22
A23: Floor Sink | B23: 0 | E23: 0 | F23: 0 | G23: =SUM(B23:F23) | H23: 2 | I23: =G23*H23
A24: Drinking Fountain | B24: 1 | E24: 0 | F24: 0 | G24: =SUM(B24:F24) | H24: 1 | I24: =G24*H24
A25: Emergency Eyewash / Shower | B25: 0 | E25: 0 | F25: 0 | G25: =SUM(B25:F25) | H25: 2 | I25: =G25*H25
A26: Hose Bib / Yard Hydrant | B26: 2 | E26: 0 | F26: 0 | G26: =SUM(B26:F26) | H26: 3 | I26: =G26*H26
A27: Wall Hydrant (Non-Freeze) | B27: 0 | E27: 0 | F27: 0 | G27: =SUM(B27:F27) | H27: 3 | I27: =G27*H27
A28: Roof Drain | B28: 0 | E28: 0 | F28: 0 | G28: =SUM(B28:F28) | H28: 2 | I28: =G28*H28
A29: Cleanout | B29: 4 | C29: 0 | D29: 0 | E29: 0 | F29: 0 | G29: =SUM(B29:F29) | H29: 0 | I29: =G29*H29
A30: Trap Primer Valve | B30: 0 | C30: 0 | D30: 0 | E30: 0 | F30: 0 | G30: =SUM(B30:F30) | H30: 0 | I30: =G30*H30
A31: ── MECHANICAL ROOM ──
A32: Water Heater Drain / Relief | B32: 1 | C32: 0 | D32: 0 | E32: 0 | F32: 0 | G32: =SUM(B32:F32) | H32: 2 | I32: =G32*H32
A33: Expansion Tank Connection | B33: 1 | C33: 0 | D33: 0 | E33: 0 | F33: 0 | G33: =SUM(B33:F33) | H33: 0 | I33: =G33*H33
A34: Backflow Preventer (1" and under) | B34: 0 | C34: 0 | D34: 0 | E34: 0 | F34: 0 | G34: =SUM(B34:F34) | H34: 0 | I34: =G34*H34
A35: Backflow Preventer (over 1") | B35: 0 | C35: 0 | D35: 0 | E35: 0 | F35: 0 | G35: =SUM(B35:F35) | H35: 0 | I35: =G35*H35
A36: Grease Interceptor (Indoor) | B36: 0 | C36: 0 | D36: 0 | E36: 0 | F36: 0 | G36: =SUM(B36:F36) | H36: 4 | I36: =G36*H36
A37: PRV Station | B37: 0 | C37: 0 | D37: 0 | E37: 0 | F37: 0 | G37: =SUM(B37:F37) | H37: 0 | I37: =G37*H37
A38: Commercial Water Heater (Tank) | B38: 1 | C38: 0 | D38: 0 | E38: 0 | F38: 0 | G38: =SUM(B38:F38) | H38: 4 | I38: =G38*H38
A39: Tankless Water Heater (commercial) | B39: 0 | C39: 0 | D39: 0 | E39: 0 | F39: 0 | G39: =SUM(B39:F39) | H39: 4 | I39: =G39*H39
A40: Mixing Valve / TMV (Tempering) | B40: 6 | C40: 0 | D40: 0 | E40: 0 | F40: 0 | G40: =SUM(B40:F40) | H40: 0 | I40: =G40*H40
A41: Recirculation Pump | B41: 0 | C41: 0 | D41: 0 | E41: 0 | F41: 0 | G41: =SUM(B41:F41) | H41: 0 | I41: =G41*H41
...

Sheet PIPE TAKEOFF
A1: BARRETT PLUMBING INC. — PIPE TAKEOFF HELPER
A2: BUILT-IN HELPER: Enter room/zone counts + avg run length to estimate LF. Then override final LF in the green cells if you have an actual takeoff.
A4: SYSTEM: DWV — Schedule 40 PVC
A5: Pipe Size | B5: Underground LF (Helper) | C5: In-Wall LF (Helper) | D5: Ceiling / Rafter LF (Helper) | E5: TOTAL HELPER LF | F5: OVERRIDE LF (manual entry) | G5: FINAL LF (used in estimate)
A6: 6" | B6: 10 | C6: 0 | D6: 0 | E6: =B6+C6+D6 | G6: =IF(F6<>"",F6,E6)
A7: 4" | B7: 120 | C7: 0 | D7: 0 | E7: =B7+C7+D7 | G7: =IF(F7<>"",F7,E7)
A8: 3" | B8: 0 | C8: 0 | D8: 0 | E8: =B8+C8+D8 | G8: =IF(F8<>"",F8,E8)
A9: 2" | B9: 0 | C9: 0 | D9: 80 | E9: =B9+C9+D9 | G9: =IF(F9<>"",F9,E9)
A10: 1-1/2" | B10: 0 | C10: 0 | D10: 130 | E10: =B10+C10+D10 | G10: =IF(F10<>"",F10,E10)
A11: 1-1/4" | B11: 0 | C11: 0 | D11: 0 | E11: =B11+C11+D11 | G11: =IF(F11<>"",F11,E11)
A12: TOTAL DWV LF | B12: =SUM(B6:B11) | C12: =SUM(C6:C11) | D12: =SUM(D6:D11) | E12: =SUM(E6:E11) | G12: =SUM(G6:G11)
A14: SYSTEM: DOMESTIC WATER SUPPLY (Cold)
A15: Pipe Size | B15: Underground LF (Helper) | C15: In-Wall LF (Helper) | D15: Ceiling / Rafter LF (Helper) | E15: TOTAL HELPER LF | F15: OVERRIDE LF (manual entry) | G15: FINAL LF (used in estimate)
A16: 2" | B16: 0 | C16: 0 | D16: 20 | E16: =B16+C16+D16 | G16: =IF(F16<>"",F16,E16)
A17: 1-1/2" | B17: 0 | C17: 0 | D17: 20 | E17: =B17+C17+D17 | G17: =IF(F17<>"",F17,E17)
A18: 1-1/4" | B18: 0 | C18: 0 | D18: 0 | E18: =B18+C18+D18 | G18: =IF(F18<>"",F18,E18)
A19: 1" | B19: 0 | C19: 0 | D19: 80 | E19: =B19+C19+D19 | G19: =IF(F19<>"",F19,E19)
A20: 3/4" | B20: 0 | C20: 0 | D20: 20 | E20: =B20+C20+D20 | G20: =IF(F20<>"",F20,E20)
A21: 1/2" | B21: 0 | C21: 280 | D21: 120 | E21: =B21+C21+D21 | G21: =IF(F21<>"",F21,E21)
A22: TOTAL COLD WATER LF | B22: =SUM(B16:B21) | C22: =SUM(C16:C21) | D22: =SUM(D16:D21) | E22: =SUM(E16:E21) | G22: =SUM(G16:G21)
A24: SYSTEM: DOMESTIC WATER SUPPLY (Hot)
A25: Pipe Size | B25: Underground LF (Helper) | C25: In-Wall LF (Helper) | D25: Ceiling / Rafter LF (Helper) | E25: TOTAL HELPER LF | F25: OVERRIDE LF (manual entry) | G25: FINAL LF (used in estimate)
A26: 1-1/2" | B26: 0 | C26: 0 | D26: 0 | E26: =B26+C26+D26 | G26: =IF(F26<>"",F26,E26)
A27: 1-1/4" | B27: 0 | C27: 0 | D27: 0 | E27: =B27+C27+D27 | G27: =IF(F27<>"",F27,E27)
A28: 1" | B28: 0 | C28: 0 | D28: 0 | E28: =B28+C28+D28 | G28: =IF(F28<>"",F28,E28)
A29: 3/4" | B29: 0 | C29: 0 | D29: 0 | E29: =B29+C29+D29 | G29: =IF(F29<>"",F29,E29)
A30: 1/2" | B30: 0 | C30: 0 | D30: 0 | E30: =B30+C30+D30 | G30: =IF(F30<>"",F30,E30)
A31: TOTAL HOT WATER LF | B31: =SUM(B26:B30) | C31: =SUM(C26:C30) | D31: =SUM(D26:D30) | E31: =SUM(E26:E30) | G31: =SUM(G26:G30)
A33: SYSTEM: HOT WATER RECIRCULATION
A34: Pipe Size | B34: Underground LF (Helper) | C34: In-Wall LF (Helper) | D34: Ceiling / Rafter LF (Helper) | E34: TOTAL HELPER LF | F34: OVERRIDE LF (manual entry) | G34: FINAL LF (used in estimate)
A35: 3/4" | B35: 0 | C35: 0 | D35: 0 | E35: =B35+C35+D35 | G35: =IF(F35<>"",F35,E35)
A36: 1/2" | B36: 0 | C36: 0 | D36: 0 | E36: =B36+C36+D36 | G36: =IF(F36<>"",F36,E36)
A37: TOTAL RECIRC LF | B37: =SUM(B35:B36) | C37: =SUM(C35:C36) | D37: =SUM(D35:D36) | E37: =SUM(E35:E36) | G37: =SUM(G35:G36)
A39: SYSTEM: COMPRESSED AIR — Black Iron
A40: Pipe Size | B40: Underground LF (Helper) | C40: In-Wall LF (Helper) | D40: Ceiling / Rafter LF (Helper) | E40: TOTAL HELPER LF | F40: OVERRIDE LF (manual entry) | G40: FINAL LF (used in estimate)
A41: 2" | B41: 0 | C41: 0 | D41: 0 | E41: =B41+C41+D41 | G41: =IF(F41<>"",F41,E41)
A42: 1-1/2" | B42: 0 | C42: 0 | D42: 0 | E42: =B42+C42+D42 | G42: =IF(F42<>"",F42,E42)
A43: 1" | B43: 0 | C43: 0 | D43: 0 | E43: =B43+C43+D43 | G43: =IF(F43<>"",F43,E43)
A44: 3/4" | B44: 0 | C44: 0 | D44: 0 | E44: =B44+C44+D44 | G44: =IF(F44<>"",F44,E44)
A45: 1/2" | B45: 0 | C45: 0 | D45: 0 | E45: =B45+C45+D45 | G45: =IF(F45<>"",F45,E45)
...

Sheet PIPE ESTIMATE
A1: BARRETT PLUMBING INC. — PIPE SYSTEM ESTIMATE
A2: Pipe LF flows from PIPE TAKEOFF sheet. Labor rates from LABOR TABLES. Material costs auto-estimated with supplier quote override.
A3: Hanger Type: | B3: Single Clevis Hanger
A4: SECTION 1: DWV — Schedule 40 PVC
A5: Pipe Size | B5: Final LF (from Takeoff) | C5: Labor Hrs (Underground) | D5: Labor Hrs (In-Wall) | E5: Labor Hrs (Ceiling) | F5: TOTAL Labor Hrs | G5: TOTAL Labor Cost ($) | H5: Est. Material Cost ($) | I5: TOTAL PIPE COST ($)
A6: 6" | B6: ='PIPE TAKEOFF'!G6 | C6: ='PIPE TAKEOFF'!B6*'LABOR TABLES'!B6*SETTINGS!$B$17 | D6: ='PIPE TAKEOFF'!C6*'LABOR TABLES'!C6*SETTINGS!$B$17 | E6: ='PIPE TAKEOFF'!D6*'LABOR TABLES'!D6*SETTINGS!$B$17 | F6: =C6+D6+E6 | G6: =F6*SETTINGS!$B$11 | H6: ='PIPE TAKEOFF'!G6*'LABOR TABLES'!E6 | I6: =G6+H6
A7: 4" | B7: ='PIPE TAKEOFF'!G7 | C7: ='PIPE TAKEOFF'!B7*'LABOR TABLES'!B7*SETTINGS!$B$17 | D7: ='PIPE TAKEOFF'!C7*'LABOR TABLES'!C7*SETTINGS!$B$17 | E7: ='PIPE TAKEOFF'!D7*'LABOR TABLES'!D7*SETTINGS!$B$17 | F7: =C7+D7+E7 | G7: =F7*SETTINGS!$B$11 | H7: ='PIPE TAKEOFF'!G7*'LABOR TABLES'!E7 | I7: =G7+H7
A8: 3" | B8: ='PIPE TAKEOFF'!G8 | C8: ='PIPE TAKEOFF'!B8*'LABOR TABLES'!B8*SETTINGS!$B$17 | D8: ='PIPE TAKEOFF'!C8*'LABOR TABLES'!C8*SETTINGS!$B$17 | E8: ='PIPE TAKEOFF'!D8*'LABOR TABLES'!D8*SETTINGS!$B$17 | F8: =C8+D8+E8 | G8: =F8*SETTINGS!$B$11 | H8: ='PIPE TAKEOFF'!G8*'LABOR TABLES'!E8 | I8: =G8+H8
A9: 2" | B9: ='PIPE TAKEOFF'!G9 | C9: ='PIPE TAKEOFF'!B9*'LABOR TABLES'!B11*SETTINGS!$B$17 | D9: ='PIPE TAKEOFF'!C9*'LABOR TABLES'!C11*SETTINGS!$B$17 | E9: ='PIPE TAKEOFF'!D9*'LABOR TABLES'!D11*SETTINGS!$B$17 | F9: =C9+D9+E9 | G9: =F9*SETTINGS!$B$11 | H9: ='PIPE TAKEOFF'!G9*'LABOR TABLES'!E11 | I9: =G9+H9
A10: 1-1/2" | B10: ='PIPE TAKEOFF'!G10 | C10: ='PIPE TAKEOFF'!B10*'LABOR TABLES'!B12*SETTINGS!$B$17 | D10: ='PIPE TAKEOFF'!C10*'LABOR TABLES'!C12*SETTINGS!$B$17 | E10: ='PIPE TAKEOFF'!D10*'LABOR TABLES'!D12*SETTINGS!$B$17 | F10: =C10+D10+E10 | G10: =F10*SETTINGS!$B$11 | H10: ='PIPE TAKEOFF'!G10*'LABOR TABLES'!E12 | I10: =G10+H10
A11: 1-1/4" | B11: ='PIPE TAKEOFF'!G11 | C11: ='PIPE TAKEOFF'!B11*'LABOR TABLES'!B13*SETTINGS!$B$17 | D11: ='PIPE TAKEOFF'!C11*'LABOR TABLES'!C13*SETTINGS!$B$17 | E11: ='PIPE TAKEOFF'!D11*'LABOR TABLES'!D13*SETTINGS!$B$17 | F11: =C11+D11+E11 | G11: =F11*SETTINGS!$B$11 | H11: ='PIPE TAKEOFF'!G11*'LABOR TABLES'!E13 | I11: =G11+H11
A12: SUBTOTAL | B12: =SUM(B6:B11) | C12: =SUM(C6:C11) | D12: =SUM(D6:D11) | E12: =SUM(E6:E11) | F12: =SUM(F6:F11) | G12: =SUM(G6:G11) | H12: =SUM(H6:H11) | I12: =SUM(I6:I11)
A13: ⬇ SUPPLIER QUOTE OVERRIDE (optional — overrides material estimate)
A14: FINAL SECTION COST (labor + material) | I14: =IF(H13<>"",G12+H13,I12)
A16: SECTION 2: DOMESTIC WATER SUPPLY (Cold)
A17: Pipe Size | B17: Final LF (from Takeoff) | C17: Labor Hrs (Underground) | D17: Labor Hrs (In-Wall) | E17: Labor Hrs (Ceiling) | F17: TOTAL Labor Hrs | G17: TOTAL Labor Cost ($) | H17: Est. Material Cost ($) | I17: TOTAL PIPE COST ($)
A18: 2" | B18: ='PIPE TAKEOFF'!G16 | C18: ='PIPE TAKEOFF'!B16*'LABOR TABLES'!M17*SETTINGS!$B$17 | D18: ='PIPE TAKEOFF'!C16*'LABOR TABLES'!N17*SETTINGS!$B$17 | E18: ='PIPE TAKEOFF'!D16*'LABOR TABLES'!O17*SETTINGS!$B$17 | F18: =C18+D18+E18 | G18: =F18*SETTINGS!$B$11 | H18: ='PIPE TAKEOFF'!G16*'LABOR TABLES'!P17 | I18: =G18+H18
A19: 1-1/2" | B19: ='PIPE TAKEOFF'!G17 | C19: ='PIPE TAKEOFF'!B17*'LABOR TABLES'!M18*SETTINGS!$B$17 | D19: ='PIPE TAKEOFF'!C17*'LABOR TABLES'!N18*SETTINGS!$B$17 | E19: ='PIPE TAKEOFF'!D17*'LABOR TABLES'!O18*SETTINGS!$B$17 | F19: =C19+D19+E19 | G19: =F19*SETTINGS!$B$11 | H19: ='PIPE TAKEOFF'!G17*'LABOR TABLES'!P18 | I19: =G19+H19
A20: 1-1/4" | B20: ='PIPE TAKEOFF'!G18 | C20: ='PIPE TAKEOFF'!B18*'LABOR TABLES'!M19*SETTINGS!$B$17 | D20: ='PIPE TAKEOFF'!C18*'LABOR TABLES'!N19*SETTINGS!$B$17 | E20: ='PIPE TAKEOFF'!D18*'LABOR TABLES'!O19*SETTINGS!$B$17 | F20: =C20+D20+E20 | G20: =F20*SETTINGS!$B$11 | H20: ='PIPE TAKEOFF'!G18*'LABOR TABLES'!P19 | I20: =G20+H20
A21: 1" | B21: ='PIPE TAKEOFF'!G19 | C21: ='PIPE TAKEOFF'!B19*'LABOR TABLES'!M20*SETTINGS!$B$17 | D21: ='PIPE TAKEOFF'!C19*'LABOR TABLES'!N20*SETTINGS!$B$17 | E21: ='PIPE TAKEOFF'!D19*'LABOR TABLES'!O20*SETTINGS!$B$17 | F21: =C21+D21+E21 | G21: =F21*SETTINGS!$B$11 | H21: ='PIPE TAKEOFF'!G19*'LABOR TABLES'!P20 | I21: =G21+H21
A22: 3/4" | B22: ='PIPE TAKEOFF'!G20 | C22: ='PIPE TAKEOFF'!B20*'LABOR TABLES'!M21*SETTINGS!$B$17 | D22: ='PIPE TAKEOFF'!C20*'LABOR TABLES'!N21*SETTINGS!$B$17 | E22: ='PIPE TAKEOFF'!D20*'LABOR TABLES'!O21*SETTINGS!$B$17 | F22: =C22+D22+E22 | G22: =F22*SETTINGS!$B$11 | H22: ='PIPE TAKEOFF'!G20*'LABOR TABLES'!P21 | I22: =G22+H22
A23: 1/2" | B23: ='PIPE TAKEOFF'!G21 | C23: ='PIPE TAKEOFF'!B21*'LABOR TABLES'!M22*SETTINGS!$B$17 | D23: ='PIPE TAKEOFF'!C21*'LABOR TABLES'!N22*SETTINGS!$B$17 | E23: ='PIPE TAKEOFF'!D21*'LABOR TABLES'!O22*SETTINGS!$B$17 | F23: =C23+D23+E23 | G23: =F23*SETTINGS!$B$11 | H23: ='PIPE TAKEOFF'!G21*'LABOR TABLES'!P22 | I23: =G23+H23
A24: SUBTOTAL | B24: =SUM(B18:B23) | C24: =SUM(C18:C23) | D24: =SUM(D18:D23) | E24: =SUM(E18:E23) | F24: =SUM(F18:F23) | G24: =SUM(G18:G23) | H24: =SUM(H18:H23) | I24: =SUM(I18:I23)
A25: ⬇ SUPPLIER QUOTE OVERRIDE (optional — overrides material estimate)
A26: FINAL SECTION COST (labor + material) | I26: =IF(H25<>"",G24+H25,I24)
A28: SECTION 3: DOMESTIC WATER SUPPLY (Hot)
A29: Pipe Size | B29: Final LF (from Takeoff) | C29: Labor Hrs (Underground) | D29: Labor Hrs (In-Wall) | E29: Labor Hrs (Ceiling) | F29: TOTAL Labor Hrs | G29: TOTAL Labor Cost ($) | H29: Est. Material Cost ($) | I29: TOTAL PIPE COST ($)
A30: 1-1/2" | B30: ='PIPE TAKEOFF'!G26 | C30: ='PIPE TAKEOFF'!B26*'LABOR TABLES'!M18*SETTINGS!$B$17 | D30: ='PIPE TAKEOFF'!C26*'LABOR TABLES'!N18*SETTINGS!$B$17 | E30: ='PIPE TAKEOFF'!D26*'LABOR TABLES'!O18*SETTINGS!$B$17 | F30: =C30+D30+E30 | G30: =F30*SETTINGS!$B$11 | H30: ='PIPE TAKEOFF'!G26*'LABOR TABLES'!P18 | I30: =G30+H30
A31: 1-1/4" | B31: ='PIPE TAKEOFF'!G27 | C31: ='PIPE TAKEOFF'!B27*'LABOR TABLES'!M19*SETTINGS!$B$17 | D31: ='PIPE TAKEOFF'!C27*'LABOR TABLES'!N19*SETTINGS!$B$17 | E31: ='PIPE TAKEOFF'!D27*'LABOR TABLES'!O19*SETTINGS!$B$17 | F31: =C31+D31+E31 | G31: =F31*SETTINGS!$B$11 | H31: ='PIPE TAKEOFF'!G27*'LABOR TABLES'!P19 | I31: =G31+H31
A32: 1" | B32: ='PIPE TAKEOFF'!G28 | C32: ='PIPE TAKEOFF'!B28*'LABOR TABLES'!M20*SETTINGS!$B$17 | D32: ='PIPE TAKEOFF'!C28*'LABOR TABLES'!N20*SETTINGS!$B$17 | E32: ='PIPE TAKEOFF'!D28*'LABOR TABLES'!O20*SETTINGS!$B$17 | F32: =C32+D32+E32 | G32: =F32*SETTINGS!$B$11 | H32: ='PIPE TAKEOFF'!G28*'LABOR TABLES'!P20 | I32: =G32+H32
A33: 3/4" | B33: ='PIPE TAKEOFF'!G29 | C33: ='PIPE TAKEOFF'!B29*'LABOR TABLES'!M21*SETTINGS!$B$17 | D33: ='PIPE TAKEOFF'!C29*'LABOR TABLES'!N21*SETTINGS!$B$17 | E33: ='PIPE TAKEOFF'!D29*'LABOR TABLES'!O21*SETTINGS!$B$17 | F33: =C33+D33+E33 | G33: =F33*SETTINGS!$B$11 | H33: ='PIPE TAKEOFF'!G29*'LABOR TABLES'!P21 | I33: =G33+H33
A34: 1/2" | B34: ='PIPE TAKEOFF'!G30 | C34: ='PIPE TAKEOFF'!B30*'LABOR TABLES'!M22*SETTINGS!$B$17 | D34: ='PIPE TAKEOFF'!C30*'LABOR TABLES'!N22*SETTINGS!$B$17 | E34: ='PIPE TAKEOFF'!D30*'LABOR TABLES'!O22*SETTINGS!$B$17 | F34: =C34+D34+E34 | G34: =F34*SETTINGS!$B$11 | H34: ='PIPE TAKEOFF'!G30*'LABOR TABLES'!P22 | I34: =G34+H34
A35: SUBTOTAL | B35: =SUM(B30:B34) | C35: =SUM(C30:C34) | D35: =SUM(D30:D34) | E35: =SUM(E30:E34) | F35: =SUM(F30:F34) | G35: =SUM(G30:G34) | H35: =SUM(H30:H34) | I35: =SUM(I30:I34)
A36: ⬇ SUPPLIER QUOTE OVERRIDE (optional — overrides material estimate)
A37: FINAL SECTION COST (labor + material) | I37: =IF(H36<>"",G35+H36,I35)
A39: SECTION 4: COMPRESSED AIR — Black Iron
A40: Pipe Size | B40: Final LF (from Takeoff) | C40: Labor Hrs (Underground) | D40: Labor Hrs (In-Wall) | E40: Labor Hrs (Ceiling) | F40: TOTAL Labor Hrs | G40: TOTAL Labor Cost ($) | H40: Est. Material Cost ($) | I40: TOTAL PIPE COST ($)
A41: 2" | B41: ='PIPE TAKEOFF'!G41 | C41: ='PIPE TAKEOFF'!B41*'LABOR TABLES'!B42*SETTINGS!$B$17 | D41: ='PIPE TAKEOFF'!C41*'LABOR TABLES'!C42*SETTINGS!$B$17 | E41: ='PIPE TAKEOFF'!D41*'LABOR TABLES'!D42*SETTINGS!$B$17 | F41: =C41+D41+E41 | G41: =F41*SETTINGS!$B$11 | H41: ='PIPE TAKEOFF'!G41*'LABOR TABLES'!E42 | I41: =G41+H41
A42: 1-1/2" | B42: ='PIPE TAKEOFF'!G42 | C42: ='PIPE TAKEOFF'!B42*'LABOR TABLES'!B43*SETTINGS!$B$17 | D42: ='PIPE TAKEOFF'!C42*'LABOR TABLES'!C43*SETTINGS!$B$17 | E42: ='PIPE TAKEOFF'!D42*'LABOR TABLES'!D43*SETTINGS!$B$17 | F42: =C42+D42+E42 | G42: =F42*SETTINGS!$B$11 | H42: ='PIPE TAKEOFF'!G42*'LABOR TABLES'!E43 | I42: =G42+H42
A43: 1" | B43: ='PIPE TAKEOFF'!G43 | C43: ='PIPE TAKEOFF'!B43*'LABOR TABLES'!B48*SETTINGS!$B$17 | D43: ='PIPE TAKEOFF'!C43*'LABOR TABLES'!C48*SETTINGS!$B$17 | E43: ='PIPE TAKEOFF'!D43*'LABOR TABLES'!D48*SETTINGS!$B$17 | F43: =C43+D43+E43 | G43: =F43*SETTINGS!$B$11 | H43: ='PIPE TAKEOFF'!G43*'LABOR TABLES'!E48 | I43: =G43+H43
...

Sheet SUBCONTRACTOR COSTS
A1: BARRETT PLUMBING INC. — SUBCONTRACTOR COSTS
A2: Enter sub costs at face value — markups handled outside this tool per your workflow. All costs pass through to the Summary sheet.
A4: Subcontractor / Line Item | B4: Unit | C4: Quantity | D4: Unit Price ($) | E4: Total Cost ($) | F4: Notes / Vendor
A5: ── EXCAVATION & SITE UTILITIES ──
A6: Trench Excavation | B6: LF | C6: 0 | D6: 4 | E6: =C6*D6
A7: Backfill & Compaction | B7: LF | C7: 0 | D7: 0 | E7: =C7*D7
A8: Boring / Directional Drill | B8: LF | C8: 0 | D8: 0 | E8: =C8*D8
A9: Site Utility Connection Fee | B9: LS | C9: 0 | D9: 0 | E9: =C9*D9
A10: ── CONCRETE WORK ──
A11: Concrete Cutting (floor slab) | B11: LF | C11: 0 | D11: 0 | E11: =C11*D11
A12: Core Drilling | B12: EA | C12: 0 | D12: 0 | E12: =C12*D12
A13: Concrete Patch / Repair | B13: SF | C13: 0 | D13: 0 | E13: =C13*D13
A14: ── INSULATION ──
A15: Pipe Insulation — 1/2" to 1" pipe | B15: LF | C15: 0 | D15: 8 | E15: =C15*D15
A16: Pipe Insulation — 1-1/4" to 2" pipe | B16: LF | C16: 0 | D16: 0 | E16: =C16*D16
A17: Pipe Insulation — 2-1/2" to 4" pipe | B17: LF | C17: 0 | D17: 0 | E17: =C17*D17
A18: ── FIRE STOP / PENETRATION SEALING ──
A19: Fire Stop Caulk / Wrap | B19: EA | C19: 0 | D19: 0 | E19: =C19*D19
A20: Intumescent Wrap | B20: EA | C20: 0 | D20: 0 | E20: =C20*D20
A21: Fire Stop Inspection | B21: LS | C21: 0 | D21: 0 | E21: =C21*D21
A22: ── TESTING & INSPECTIONS ──
A23: Third-Party Testing / Balancing | B23: LS | C23: 0 | D23: 0 | E23: =C23*D23
A24: Permit / Inspection Fees | B24: LS | C24: 0 | D24: 0 | E24: =C24*D24
A25: ── OTHER SUBCONTRACTORS ──
A26: Lift Rental | B26: DAY | C26: 0 | D26: 50 | E26: =C26*D26
A27: Other Sub 2 | C27: 0 | D27: 0 | E27: =C27*D27
A28: Other Sub 3 | C28: 0 | D28: 0 | E28: =C28*D28
A30: TOTAL SUBCONTRACTOR COSTS | E30: =SUMIF(E5:E28,">0")

Sheet SLEEVE SCHEDULE
A1: BARRETT PLUMBING INC. — MASONRY SLEEVE SCHEDULE
A2: Enter sleeve counts by size and wall type. Site visit coordination hours auto-calculated. Material cost auto-estimated with override available.
A4: Sleeve Size | B4: Wall Type | C4: Qty Needed | D4: Unit Material Cost ($) | E4: Total Material Cost | F4: Install Hrs/Sleeve | G4: Total Install Hrs | H4: Site Visits Required | I4: Hrs/Visit (Crew) | J4: Total Coordination Hrs
A5: 2" Sleeve | B5: =INPUT!B18 | C5: 1 | D5: 12 | E5: =C5*D5 | F5: 0.5 | G5: =C5*F5*SETTINGS!$B$17 | H5: 1 | I5: 2 | J5: =C5*H5*I5*SETTINGS!$B$17
A6: 2" Sleeve | B6: Tilt-Up | C6: 0 | D6: 14 | E6: =C6*D6 | F6: 0.5 | G6: =C6*F6*SETTINGS!$B$17 | H6: 1 | I6: 2 | J6: =C6*H6*I6*SETTINGS!$B$17
A7: 3" Sleeve | B7: =INPUT!B18 | C7: 0 | D7: 16 | E7: =C7*D7 | F7: 0.75 | G7: =C7*F7*SETTINGS!$B$17 | H7: 1 | I7: 2 | J7: =C7*H7*I7*SETTINGS!$B$17
A8: 3" Sleeve | B8: Tilt-Up | C8: 0 | D8: 18 | E8: =C8*D8 | F8: 0.75 | G8: =C8*F8*SETTINGS!$B$17 | H8: 1 | I8: 2 | J8: =C8*H8*I8*SETTINGS!$B$17
A9: 4" Sleeve | B9: =INPUT!B18 | C9: 0 | D9: 22 | E9: =C9*D9 | F9: 1 | G9: =C9*F9*SETTINGS!$B$17 | H9: 1 | I9: 2 | J9: =C9*H9*I9*SETTINGS!$B$17
A10: 4" Sleeve | B10: Tilt-Up | C10: 0 | D10: 26 | E10: =C10*D10 | F10: 1 | G10: =C10*F10*SETTINGS!$B$17 | H10: 1 | I10: 2 | J10: =C10*H10*I10*SETTINGS!$B$17
A11: 6" Sleeve | B11: =INPUT!B18 | C11: 0 | D11: 38 | E11: =C11*D11 | F11: 1.5 | G11: =C11*F11*SETTINGS!$B$17 | H11: 2 | I11: 2 | J11: =C11*H11*I11*SETTINGS!$B$17
A12: 6" Sleeve | B12: Tilt-Up | C12: 0 | D12: 44 | E12: =C12*D12 | F12: 1.5 | G12: =C12*F12*SETTINGS!$B$17 | H12: 2 | I12: 2 | J12: =C12*H12*I12*SETTINGS!$B$17
A13: 8" Sleeve | B13: =INPUT!B18 | C13: 0 | D13: 55 | E13: =C13*D13 | F13: 2 | G13: =C13*F13*SETTINGS!$B$17 | H13: 2 | I13: 2 | J13: =C13*H13*I13*SETTINGS!$B$17
A14: 8" Sleeve | B14: Tilt-Up | C14: 0 | D14: 62 | E14: =C14*D14 | F14: 2 | G14: =C14*F14*SETTINGS!$B$17 | H14: 2 | I14: 2 | J14: =C14*H14*I14*SETTINGS!$B$17
A15: 10" Sleeve | B15: =INPUT!B18 | C15: 0 | D15: 75 | E15: =C15*D15 | F15: 2.5 | G15: =C15*F15*SETTINGS!$B$17 | H15: 3 | I15: 2 | J15: =C15*H15*I15*SETTINGS!$B$17
A16: 10" Sleeve | B16: Tilt-Up | C16: 0 | D16: 85 | E16: =C16*D16 | F16: 2.5 | G16: =C16*F16*SETTINGS!$B$17 | H16: 3 | I16: 2 | J16: =C16*H16*I16*SETTINGS!$B$17
A17: Custom Size | B17: Other | C17: 0 | D17: 0 | E17: =C17*D17 | F17: 0 | G17: =C17*F17*SETTINGS!$B$17 | H17: 1 | I17: 2 | J17: =C17*H17*I17*SETTINGS!$B$17
A19: SLEEVE TOTALS | C19: =SUM(C5:C17) | E19: =SUM(E5:E17) | G19: =SUM(G5:G17) | J19: =SUM(J5:J17)
A21: SITE VISIT COORDINATION SCHEDULE
A22: Visit # | B22: Purpose / Phase | C22: Scheduled Date | D22: Est. Hours on Site | E22: Crew Members | F22: Total Crew Hours | G22: Notes
A23: 1 | B23: Pre-pour sleeve set (masonry phase)
A24: 2 | B24: Verify sleeve locations before pour
A25: 3
A26: 4
A27: 5
A28: 6
A29: 7
A30: 8

Sheet SUMMARY
A1: BARRETT PLUMBING INC. — COMMERCIAL ESTIMATE SUMMARY
A3: PROJECT | B3: =INPUT!B5
A4: CLIENT / GC | B4: =INPUT!B6 | D4: DATE | E4: =INPUT!B10
A5: BUILDING TYPE | B5: =INPUT!B15 | D5: ESTIMATOR | E5: =INPUT!B9
A7: LABOR HOURS SUMMARY | B7: Labor Hrs
A8: DWV Pipe System — Sch 40 PVC | B8: ='PIPE ESTIMATE'!F12 | D8: Blended Rate ($/hr) | E8: =SETTINGS!B11
A9: Domestic Water Supply (Cold) | B9: ='PIPE ESTIMATE'!F24 | D9: Est. Crew Days (8 hr) | E9: =CEILING(B18/8,1)
A10: Domestic Water Supply (Hot) | B10: ='PIPE ESTIMATE'!F35 | D10: Cost per Labor Hour | E10: =IF(B18>0,E33/B18,0)
A11: Hot Water Recirculation | B11: ='PIPE ESTIMATE'!F60
A12: Compressed Air — Black Iron | B12: ='PIPE ESTIMATE'!F46
A13: CMU Block Wall Drops | B13: ='PIPE ESTIMATE'!F53
A14: Fixture & Specialty Labor | B14: ='FIXTURE ESTIMATE'!D44
A15: Hanger System Labor | B15: ='FIXTURE ESTIMATE'!D54
A16: Masonry Sleeve Labor | B16: ='SLEEVE SCHEDULE'!G19+'SLEEVE SCHEDULE'!J19
A17: Plumbing Demolition Labor | B17: ='DEMO ESTIMATE'!G37+'DEMO ESTIMATE'!D68
A18: TOTAL LABOR HOURS | B18: =SUM(B8:B17)
A20: COST CATEGORY | B20: Labor Cost ($) | C20: Material Cost ($) | D20: Sub / Other ($) | E20: CATEGORY TOTAL ($)
A21: DWV Pipe System — Sch 40 PVC | B21: ='PIPE ESTIMATE'!G12 | C21: ='PIPE ESTIMATE'!I14-'PIPE ESTIMATE'!G12 | D21: - | E21: =B21+C21
A22: Domestic Water Supply (Cold) | B22: ='PIPE ESTIMATE'!G24 | C22: ='PIPE ESTIMATE'!I26-'PIPE ESTIMATE'!G24 | D22: - | E22: =B22+C22
A23: Domestic Water Supply (Hot) | B23: ='PIPE ESTIMATE'!G35 | C23: ='PIPE ESTIMATE'!I37-'PIPE ESTIMATE'!G35 | D23: - | E23: =B23+C23
A24: Hot Water Recirculation | B24: ='PIPE ESTIMATE'!G60 | C24: ='PIPE ESTIMATE'!I62-'PIPE ESTIMATE'!G60 | D24: - | E24: =B24+C24
A25: Compressed Air — Black Iron | B25: ='PIPE ESTIMATE'!G46 | C25: ='PIPE ESTIMATE'!I48-'PIPE ESTIMATE'!G46 | D25: - | E25: =B25+C25
A26: CMU Block Wall Drops | B26: ='PIPE ESTIMATE'!G53 | C26: - | D26: - | E26: =B26
A27: Fixture & Specialty Labor | B27: ='FIXTURE ESTIMATE'!E44 | C27: - | D27: - | E27: =B27
A28: Hanger System Labor | B28: ='FIXTURE ESTIMATE'!E54 | C28: - | D28: - | E28: =B28
A29: Masonry Sleeve Material & Labor | B29: =('SLEEVE SCHEDULE'!G19+'SLEEVE SCHEDULE'!J19)*SETTINGS!B11 | C29: ='SLEEVE SCHEDULE'!E19 | D29: - | E29: =B29+C29
A30: Subcontractor Costs (pass-through) | B30: - | C30: - | D30: ='SUBCONTRACTOR COSTS'!E30 | E30: =D30
A31: Mobilization & Travel | B31: =SETTINGS!B30+SETTINGS!B31*SETTINGS!B32 | C31: - | D31: - | E31: =B31
A32: Plumbing Demolition Labor | B32: ='DEMO ESTIMATE'!H37+'DEMO ESTIMATE'!H68 | C32: - | D32: - | E32: =B32
A33: SUBTOTAL — DIRECT COSTS | B33: =SUM(B21:B32) | C33: =SUM(C21:C32) | D33: =SUM(D21:D32) | E33: =SUM(E21:E32)
A35: OVERHEAD, PROFIT & ADJUSTMENTS
A36: Overhead & Burden | B36: =SETTINGS!B22 | E36: =E33*B36
A37: Profit Margin | B37: =SETTINGS!B23 | E37: =E33*B37
A38: Bond / Insurance | B38: =SETTINGS!B24 | E38: =E33*B38
A39: Material Markup (on material costs) | B39: =SETTINGS!B21 | E39: =C33*B39
A41: SUBTOTAL — WITH OVERHEAD & PROFIT | E41: =E33+SUM(E36:E39)
A43: PERMIT & INSPECTION FEES
A44: Permit Fee (enter from AHJ quote or estimate) | E44: 0
A45: Plan Review Fee | E45: 0
A46: Inspection Fees (est.) | E46: 0
...

Sheet LABOR TABLES
A1: BARRETT PLUMBING INC. — COMMERCIAL LABOR TABLES
A2: Labor hours per LF and per unit. Blue cells = adjustable inputs. Based on commercial installation standards — adjust from actuals over time.
A4: TABLE A — DWV PIPE INSTALLATION (Schedule 40 PVC) | H4: Item | I4: Labor Hours Each | J4: Unit Material Cost ($)
A5: Pipe Size | B5: Underground (hrs/LF) | C5: In-Wall (hrs/LF) | D5: Ceiling/Rafter (hrs/LF) | E5: Unit Material Cost ($/LF) | F5: Notes | H5: TABLE D — FIXTURE ROUGH-IN & SET LABOR
A6: 6" Sch 40 PVC | B6: 0.14 | C6: 0.12 | D6: 0.16 | E6: 7.5
A7: 4" Sch 40 PVC | B7: 0.13 | C7: 0.1 | D7: 0.16 | E7: 4.5 | H7: Water Closet (flush valve) — Rough-In | I7: 3.5
A8: 3" Sch 40 PVC | B8: 0.12 | C8: 0.09 | D8: 0.16 | E8: 3.2 | H8: Water Closet (flush valve) — Final Set | I8: 1.5
H9: Water Closet (tank type) — Rough-In | I9: 2.5
H10: Water Closet (tank type) — Final Set | I10: 1
A11: 2" Sch 40 PVC | B11: 0.11 | C11: 0.08 | D11: 0.16 | E11: 2.1 | H11: Urinal — Rough-In | I11: 2.5
A12: 1-1/2" Sch 40 PVC | B12: 0.11 | C12: 0.07 | D12: 0.16 | E12: 1.6 | H12: Urinal — Final Set | I12: 1.5
A13: 1-1/4" Sch 40 PVC | B13: 0.11 | C13: 0.06 | D13: 0.16 | E13: 1.3 | H13: Lavatory — Rough-In | I13: 2.5
H14: Lavatory — Final Set | I14: 1.5
A15: TABLE B — DOMESTIC WATER SUPPLY INSTALLATION | H15: 3-Compartment Sink — Rough-In | I15: 5 | L15: TABLE B2 — WATER SUPPLY RATES IN USE (follows INPUT → Water Supply Pipe Material)
A16: Pipe Size / Material | B16: Underground (hrs/LF) | C16: In-Wall (hrs/LF) | D16: Ceiling/Rafter (hrs/LF) | E16: Unit Material Cost ($/LF) | F16: Notes | H16: 3-Compartment Sink — Final Set | I16: 3 | L16: Pipe Size | M16: Underground (hrs/LF) | N16: In-Wall (hrs/LF) | O16: Ceiling/Rafter (hrs/LF) | P16: Unit Material Cost ($/LF) | Q16: Rates From
A17: 2" Type L Copper | B17: 0.12 | C17: 0.17 | D17: 0.18 | E17: 9.8 | H17: Mop Sink / Service Sink | I17: 4 | L17: 2" | M17: =IF(INPUT!$E$12="Type K Copper",B23,B17) | N17: =IF(INPUT!$E$12="Type K Copper",C23,C17) | O17: =IF(INPUT!$E$12="Type K Copper",D23,D17) | P17: =IF(INPUT!$E$12="Type K Copper",E23,E17) | Q17: =IF(INPUT!$E$12="Type K Copper","Type K Copper","Type L Copper")
A18: 1-1/2" Type L Copper | B18: 0.1 | C18: 0.16 | D18: 0.16 | E18: 7.2 | H18: Floor Drain (2") | I18: 1.5 | L18: 1-1/2" | M18: =IF(INPUT!$E$12="Type K Copper",B24,B18) | N18: =IF(INPUT!$E$12="Type K Copper",C24,C18) | O18: =IF(INPUT!$E$12="Type K Copper",D24,D18) | P18: =IF(INPUT!$E$12="Type K Copper",E24,E18) | Q18: =IF(INPUT!$E$12="Type K Copper","Type K Copper","Type L Copper")
A19: 1-1/4" Type L Copper | B19: 0.09 | C19: 0.15 | D19: 0.15 | E19: 5.8 | H19: Floor Drain (3") | I19: 1.5 | L19: 1-1/4" | M19: =IF(INPUT!$E$12="Type K Copper",B25,B19) | N19: =IF(INPUT!$E$12="Type K Copper",C25,C19) | O19: =IF(INPUT!$E$12="Type K Copper",D25,D19) | P19: =IF(INPUT!$E$12="Type K Copper",E25,E19) | Q19: =IF(INPUT!$E$12="Type K Copper","Type K Copper","Type L Copper")
A20: 1" Type L Copper | B20: 0.08 | C20: 0.15 | D20: 0.14 | E20: 4.5 | H20: Floor Drain (4") | I20: 1.5 | L20: 1" | M20: =IF(INPUT!$E$12="PEX-B",B36,IF(INPUT!$E$12="Type K Copper",B26,B20)) | N20: =IF(INPUT!$E$12="PEX-B",C36,IF(INPUT!$E$12="Type K Copper",C26,C20)) | O20: =IF(INPUT!$E$12="PEX-B",D36,IF(INPUT!$E$12="Type K Copper",D26,D20)) | P20: =IF(INPUT!$E$12="PEX-B",E36,IF(INPUT!$E$12="Type K Copper",E26,E20)) | Q20: =IF(INPUT!$E$12="PEX-B","PEX-B",IF(INPUT!$E$12="Type K Copper","Type K Copper","Type L Copper"))
A21: 3/4" Type L Copper | B21: 0.07 | C21: 0.14 | D21: 0.12 | E21: 3.4 | H21: Floor Sink | I21: 2 | L21: 3/4" | M21: =IF(INPUT!$E$12="PEX-B",B37,IF(INPUT!$E$12="Type K Copper",B27,B21)) | N21: =IF(INPUT!$E$12="PEX-B",C37,IF(INPUT!$E$12="Type K Copper",C27,C21)) | O21: =IF(INPUT!$E$12="PEX-B",D37,IF(INPUT!$E$12="Type K Copper",D27,D21)) | P21: =IF(INPUT!$E$12="PEX-B",E37,IF(INPUT!$E$12="Type K Copper",E27,E21)) | Q21: =IF(INPUT!$E$12="PEX-B","PEX-B",IF(INPUT!$E$12="Type K Copper","Type K Copper","Type L Copper"))
A22: 1/2" Type L Copper | B22: 0.06 | C22: 0.14 | D22: 0.12 | E22: 2.6 | H22: Drinking Fountain — Rough-In | I22: 2.5 | L22: 1/2" | M22: =IF(INPUT!$E$12="PEX-B",B38,IF(INPUT!$E$12="Type K Copper",B28,B22)) | N22: =IF(INPUT!$E$12="PEX-B",C38,IF(INPUT!$E$12="Type K Copper",C28,C22)) | O22: =IF(INPUT!$E$12="PEX-B",D38,IF(INPUT!$E$12="Type K Copper",D28,D22)) | P22: =IF(INPUT!$E$12="PEX-B",E38,IF(INPUT!$E$12="Type K Copper",E28,E22)) | Q22: =IF(INPUT!$E$12="PEX-B","PEX-B",IF(INPUT!$E$12="Type K Copper","Type K Copper","Type L Copper"))
A23: 2" Type K Copper | B23: 0.12 | C23: 0.17 | D23: 0.18 | E23: 12 | H23: Drinking Fountain — Final Set | I23: 1.5 | L23: PEX-B has no rates above 1" — those sizes use Type L copper. PIPE ESTIMATE water sections pull their rates from this table.
A24: 1-1/2" Type K Copper | B24: 0.1 | C24: 0.16 | D24: 0.16 | E24: 8.5 | H24: Emergency Eyewash / Shower | I24: 3
A25: 1-1/4" Type K Copper | B25: 0.09 | C25: 0.15 | D25: 0.15 | E25: 7 | H25: Hose Bib — Commercial | I25: 1
A26: 1" Type K Copper | B26: 0.08 | C26: 0.15 | D26: 0.14 | E26: 5.5 | H26: Wall Hydrant (non-freeze) | I26: 2
A27: 3/4" Type K Copper | B27: 0.07 | C27: 0.14 | D27: 0.12 | E27: 4.5 | H27: Lavatory (Group / Multiple) — Rough-In + Set | I27: 3
A28: 1/2" Type K Copper | B28: 0.06 | C28: 0.14 | D28: 0.12 | E28: 3.8 | H28: Prep Sink / Hand Sink — Rough-In + Set | I28: 5
H29: Kitchen Sink (Double Basin) — Rough-In + Set | I29: 10
H30: Kitchen Sink (Single Basin) — Rough-In + Set | I30: 8
H31: Commercial Dishwasher Connection | I31: 1.5
H32: Ice Maker Connection | I32: 1.5
H33: Roof Drain | I33: 2
H34: Cleanout (Double / 2-Way) | I34: 1
H35: TABLE E — SPECIALTY EQUIPMENT LABOR
A36: 1" PEX-B | B36: 0.06 | C36: 0.12 | D36: 0.12 | E36: 1.8 | H36: Grease Interceptor (indoor) | I36: 6
A37: 3/4" PEX-B | B37: 0.05 | C37: 0.12 | D37: 0.12 | E37: 1.2 | H37: Grease Interceptor (exterior / in-ground) | I37: 12
A38: 1/2" PEX-B | B38: 0.04 | C38: 0.12 | D38: 0.12 | E38: 0.85 | H38: RPZ Backflow Preventer (1" and under) | I38: 3.5
H39: RPZ Backflow Preventer (1-1/4" – 2") | I39: 5
A40: TABLE C — COMPRESSED AIR (Black Iron) | H40: PRV Station (complete) | I40: 4
A41: Pipe Size | B41: Underground (hrs/LF) | C41: In-Wall (hrs/LF) | D41: Ceiling/Rafter (hrs/LF) | E41: Unit Material Cost ($/LF) | F41: Notes | H41: Expansion Tank (up to 50 gal) | I41: 1.5
...

Sheet FIXTURE ESTIMATE
A1: BARRETT PLUMBING INC. — FIXTURE & SPECIALTY LABOR ESTIMATE
A2: Quantities pull from FIXTURE SCHEDULE. Labor hours pull from LABOR TABLES Table D & E. Override quantities in blue cells if different from fixture schedule.
A4: Fixture / Item | B4: Qty (from Schedule) | C4: Labor Hrs Each | D4: TOTAL Labor Hrs | E4: Labor Cost ($) | F4: Notes
A5: ── RESTROOM FIXTURES ──
A6: Water Closet (Flush Valve) — Rough-In + Set | B6: ='FIXTURE SCHEDULE'!G6 | C6: =('LABOR TABLES'!I7+'LABOR TABLES'!I8)*SETTINGS!$B$17 | D6: =B6*C6 | E6: =D6*SETTINGS!$B$11
A7: Urinal (Flush Valve) — Rough-In + Set | B7: ='FIXTURE SCHEDULE'!G8 | C7: =('LABOR TABLES'!I11+'LABOR TABLES'!I12)*SETTINGS!$B$17 | D7: =B7*C7 | E7: =D7*SETTINGS!$B$11
A8: Lavatory (Single) — Rough-In + Set | B8: ='FIXTURE SCHEDULE'!G9 | C8: =('LABOR TABLES'!I13+'LABOR TABLES'!I14)*SETTINGS!$B$17 | D8: =B8*C8 | E8: =D8*SETTINGS!$B$11
A9: Water Closet (Tank Type) — Rough-In + Set | B9: ='FIXTURE SCHEDULE'!G7 | C9: =('LABOR TABLES'!I9+'LABOR TABLES'!I10)*SETTINGS!$B$17 | D9: =B9*C9 | E9: =D9*SETTINGS!$B$11
A10: Lavatory (Group / Multiple) — Rough-In + Set | B10: ='FIXTURE SCHEDULE'!G10 | C10: ='LABOR TABLES'!I27*SETTINGS!$B$17 | D10: =B10*C10 | E10: =D10*SETTINGS!$B$11
A11: ── KITCHEN / FOOD SERVICE ──
A12: 3-Compartment Sink — Rough-In + Set | B12: ='FIXTURE SCHEDULE'!G12 | C12: =('LABOR TABLES'!I15+'LABOR TABLES'!I16)*SETTINGS!$B$17 | D12: =B12*C12 | E12: =D12*SETTINGS!$B$11
A13: Prep Sink / Hand Sink | B13: ='FIXTURE SCHEDULE'!G13 | C13: ='LABOR TABLES'!I28*SETTINGS!$B$17 | D13: =B13*C13 | E13: =D13*SETTINGS!$B$11
A14: Mop Sink / Service Sink | B14: ='FIXTURE SCHEDULE'!G19 | C14: ='LABOR TABLES'!I17*SETTINGS!$B$17 | D14: =B14*C14 | E14: =D14*SETTINGS!$B$11
A15: Kitchen Sink (Double Basin) — Rough-In + Set | B15: ='FIXTURE SCHEDULE'!G14 | C15: ='LABOR TABLES'!I29*SETTINGS!$B$17 | D15: =B15*C15 | E15: =D15*SETTINGS!$B$11
A16: Kitchen Sink (Single Basin) — Rough-In + Set | B16: ='FIXTURE SCHEDULE'!G15 | C16: ='LABOR TABLES'!I30*SETTINGS!$B$17 | D16: =B16*C16 | E16: =D16*SETTINGS!$B$11
A17: Ice Maker Connection | B17: ='FIXTURE SCHEDULE'!G17 | C17: ='LABOR TABLES'!I32*SETTINGS!$B$17 | D17: =B17*C17 | E17: =D17*SETTINGS!$B$11
A18: Commercial Dishwasher Connection | B18: ='FIXTURE SCHEDULE'!G16 | C18: ='LABOR TABLES'!I31*SETTINGS!$B$17 | D18: =B18*C18 | E18: =D18*SETTINGS!$B$11
A19: ── UTILITY ──
A20: Floor Drain (2") | B20: ='FIXTURE SCHEDULE'!G20 | C20: ='LABOR TABLES'!I18*SETTINGS!$B$17 | D20: =B20*C20 | E20: =D20*SETTINGS!$B$11
A21: Floor Drain (3") | B21: ='FIXTURE SCHEDULE'!G21 | C21: ='LABOR TABLES'!I19*SETTINGS!$B$17 | D21: =B21*C21 | E21: =D21*SETTINGS!$B$11
A22: Floor Drain (4") | B22: ='FIXTURE SCHEDULE'!G22 | C22: ='LABOR TABLES'!I20*SETTINGS!$B$17 | D22: =B22*C22 | E22: =D22*SETTINGS!$B$11
A23: Floor Sink | B23: ='FIXTURE SCHEDULE'!G23 | C23: ='LABOR TABLES'!I21*SETTINGS!$B$17 | D23: =B23*C23 | E23: =D23*SETTINGS!$B$11
A24: Drinking Fountain | B24: ='FIXTURE SCHEDULE'!G24 | C24: =('LABOR TABLES'!I22+'LABOR TABLES'!I23)*SETTINGS!$B$17 | D24: =B24*C24 | E24: =D24*SETTINGS!$B$11
A25: Emergency Eyewash / Shower | B25: ='FIXTURE SCHEDULE'!G25 | C25: ='LABOR TABLES'!I24*SETTINGS!$B$17 | D25: =B25*C25 | E25: =D25*SETTINGS!$B$11
A26: Hose Bib (Commercial) | B26: ='FIXTURE SCHEDULE'!G26 | C26: ='LABOR TABLES'!I25*SETTINGS!$B$17 | D26: =B26*C26 | E26: =D26*SETTINGS!$B$11
A27: Wall Hydrant (Non-Freeze) | B27: ='FIXTURE SCHEDULE'!G27 | C27: ='LABOR TABLES'!I26*SETTINGS!$B$17 | D27: =B27*C27 | E27: =D27*SETTINGS!$B$11
A28: Roof Drain | B28: ='FIXTURE SCHEDULE'!G28 | C28: ='LABOR TABLES'!I33*SETTINGS!$B$17 | D28: =B28*C28 | E28: =D28*SETTINGS!$B$11
A29: Cleanout (Double / 2-Way) | B29: ='FIXTURE SCHEDULE'!G29 | C29: ='LABOR TABLES'!I34*SETTINGS!$B$17 | D29: =B29*C29 | E29: =D29*SETTINGS!$B$11
A30: Trap Primer Valve | B30: ='FIXTURE SCHEDULE'!G30 | C30: ='LABOR TABLES'!I45*SETTINGS!$B$17 | D30: =B30*C30 | E30: =D30*SETTINGS!$B$11
A31: ── SPECIALTY EQUIPMENT ──
A32: Grease Interceptor (Indoor) | B32: ='FIXTURE SCHEDULE'!G36 | C32: ='LABOR TABLES'!I36*SETTINGS!$B$17 | D32: =B32*C32 | E32: =D32*SETTINGS!$B$11
A33: RPZ Backflow Preventer (1" and under) | B33: ='FIXTURE SCHEDULE'!G34 | C33: ='LABOR TABLES'!I38*SETTINGS!$B$17 | D33: =B33*C33 | E33: =D33*SETTINGS!$B$11
A34: PRV Station | B34: ='FIXTURE SCHEDULE'!G37 | C34: ='LABOR TABLES'!I40*SETTINGS!$B$17 | D34: =B34*C34 | E34: =D34*SETTINGS!$B$11
A35: Commercial Water Heater (Tank) | B35: ='FIXTURE SCHEDULE'!G38 | C35: ='LABOR TABLES'!I42*SETTINGS!$B$17 | D35: =B35*C35 | E35: =D35*SETTINGS!$B$11
A36: Expansion Tank | B36: ='FIXTURE SCHEDULE'!G33 | C36: ='LABOR TABLES'!I41*SETTINGS!$B$17 | D36: =B36*C36 | E36: =D36*SETTINGS!$B$11
A37: Grease Interceptor (Exterior / In-Ground) | B37: ='FIXTURE SCHEDULE'!G42 | C37: ='LABOR TABLES'!I37*SETTINGS!$B$17 | D37: =B37*C37 | E37: =D37*SETTINGS!$B$11
A38: RPZ Backflow Preventer (1-1/4” – 2”) | B38: ='FIXTURE SCHEDULE'!G35 | C38: ='LABOR TABLES'!I39*SETTINGS!$B$17 | D38: =B38*C38 | E38: =D38*SETTINGS!$B$11
A39: Tankless Water Heater (Commercial) | B39: ='FIXTURE SCHEDULE'!G39 | C39: ='LABOR TABLES'!I43*SETTINGS!$B$17 | D39: =B39*C39 | E39: =D39*SETTINGS!$B$11
A40: Water Heater Drain / Relief Valve | B40: ='FIXTURE SCHEDULE'!G32 | C40: ='LABOR TABLES'!I44*SETTINGS!$B$17 | D40: =B40*C40 | E40: =D40*SETTINGS!$B$11
A41: Mixing Valve / TMV (Tempering) | B41: ='FIXTURE SCHEDULE'!G40 | C41: ='LABOR TABLES'!I46*SETTINGS!$B$17 | D41: =B41*C41 | E41: =D41*SETTINGS!$B$11
...

Sheet ACTUALS TRACKER
A1: BARRETT PLUMBING INC. — COMMERCIAL ACTUALS TRACKER
A2: Log actuals after job completion. Builds your commercial labor rate database over time. Win/Loss tracking improves bid accuracy.
A4: # | B4: Project Name | C4: Building Type | D4: Bid Date | E4: Est. Labor Hrs | F4: Act. Labor Hrs | G4: Est. Pipe LF | H4: Act. Pipe LF | I4: Est. Total ($) | J4: Act. Total ($) | K4: Variance ($) | L4: Variance % | M4: Won / Lost | N4: Notes | O4: Key Lessons
A5: 1 | K5: =IF(AND(I5<>"",J5<>""),J5-I5,"") | L5: =IF(AND(I5<>"",J5<>"",I5<>0),(J5-I5)/I5,"")
A6: 2 | K6: =IF(AND(I6<>"",J6<>""),J6-I6,"") | L6: =IF(AND(I6<>"",J6<>"",I6<>0),(J6-I6)/I6,"")
A7: 3 | K7: =IF(AND(I7<>"",J7<>""),J7-I7,"") | L7: =IF(AND(I7<>"",J7<>"",I7<>0),(J7-I7)/I7,"")
A8: 4 | K8: =IF(AND(I8<>"",J8<>""),J8-I8,"") | L8: =IF(AND(I8<>"",J8<>"",I8<>0),(J8-I8)/I8,"")
A9: 5 | K9: =IF(AND(I9<>"",J9<>""),J9-I9,"") | L9: =IF(AND(I9<>"",J9<>"",I9<>0),(J9-I9)/I9,"")
A10: 6 | K10: =IF(AND(I10<>"",J10<>""),J10-I10,"") | L10: =IF(AND(I10<>"",J10<>"",I10<>0),(J10-I10)/I10,"")
A11: 7 | K11: =IF(AND(I11<>"",J11<>""),J11-I11,"") | L11: =IF(AND(I11<>"",J11<>"",I11<>0),(J11-I11)/I11,"")
A12: 8 | K12: =IF(AND(I12<>"",J12<>""),J12-I12,"") | L12: =IF(AND(I12<>"",J12<>"",I12<>0),(J12-I12)/I12,"")
A13: 9 | K13: =IF(AND(I13<>"",J13<>""),J13-I13,"") | L13: =IF(AND(I13<>"",J13<>"",I13<>0),(J13-I13)/I13,"")
A14: 10 | K14: =IF(AND(I14<>"",J14<>""),J14-I14,"") | L14: =IF(AND(I14<>"",J14<>"",I14<>0),(J14-I14)/I14,"")
A15: 11 | K15: =IF(AND(I15<>"",J15<>""),J15-I15,"") | L15: =IF(AND(I15<>"",J15<>"",I15<>0),(J15-I15)/I15,"")
A16: 12 | K16: =IF(AND(I16<>"",J16<>""),J16-I16,"") | L16: =IF(AND(I16<>"",J16<>"",I16<>0),(J16-I16)/I16,"")
... A29: 25 | K29: =IF(AND(I29<>"",J29<>""),J29-I29,"") | L29: =IF(AND(I29<>"",J29<>"",I29<>0),(J29-I29)/I29,"")
A31: SUMMARY STATISTICS
A32: Total Jobs Tracked | D32: =COUNTA(B5:B29)
A33: Jobs Won | D33: =COUNTIF(M5:M29,"Won")
A34: Win Rate % | D34: =IF(COUNTA(B5:B29)>0,COUNTIF(M5:M29,"Won")/COUNTA(B5:B29),0)
A35: Avg Labor Variance % | D35: =IFERROR(AVERAGE(L5:L29),0)
A36: Avg Cost Variance ($) | D36: =IFERROR(AVERAGE(K5:K29),0)

Sheet SETTINGS
A1: BARRETT PLUMBING INC. — COMMERCIAL ESTIMATOR SETTINGS
A2: Configure labor rates, overhead, and markup. All other sheets reference these values.
A4: LABOR RATES | F4: MICHIGAN COMMERCIAL PERMIT FEE REFERENCE
A5: Master Plumber — Billable Rate ($/hr) | B5: =66.14 + 42 | C5: Fully burdened field billing rate | F5: Michigan commercial permit fees are typically valuation-based.
A6: Journeyman Plumber — Billable Rate ($/hr) | B6: =66.14+40 | F6: Project Valuation | G6: Est. Permit Fee
A7: Apprentice Plumber — Billable Rate ($/hr) | B7: =66.14+23 | F7: Up to $10,000 | G7: $150 – $250
A8: Default Crew Mix — Master Hours % | B8: 0 | C8: e.g. 30% of hours billed at master rate | F8: $10,001 – $25,000 | G8: $250 – $450
A9: Default Crew Mix — Journeyman Hours % | B9: 0.334 | F9: $25,001 – $50,000 | G9: $450 – $750
A10: Default Crew Mix — Apprentice Hours % | B10: 0.666 | F10: $50,001 – $100,000 | G10: $750 – $1,200
A11: Blended Labor Rate ($/hr) — AUTO | B11: =B8*B5+B9*B6+B10*B7 | C11: Auto-calculated from mix above | F11: $100,001 – $250,000 | G11: $1,200 – $2,500
A13: COMPLEXITY MULTIPLIERS | B13: COMPLEXITY MULTIPLIERS | C13: COMPLEXITY MULTIPLIERS | D13: COMPLEXITY MULTIPLIERS
A14: Normal | B14: 0 | C14: Labor hour adder — 0% = no change
A15: High | B15: 0.15 | C15: Labor hour adder — 15% increase
A16: Very High | B16: 0.25 | C16: Labor hour adder — 25% increase
A17: Active Complexity Multiplier | B17: =1+IF(INPUT!E10="High",B15,IF(INPUT!E10="Very High",B16,B14)) | C17: Auto: 1 + selected complexity adder
F19: $250,001 – $500,000 | G19: $2,500 – $4,500
A20: MARKUP & OVERHEAD | F20: $500,001+ | G20: Contact jurisdiction
A21: Material Markup % | B21: 0.25
A22: Overhead & Burden % | B22: 0.58 | F22: Plan Review Fee (typical) | G22: 65% of permit fee
A23: Profit Margin % | B23: 0.23 | F23: Inspection Fee (each trip) | G23: $75 – $150
A24: Bond / Insurance % (if applicable) | B24: 0 | F24: Re-inspection Fee | G24: $100 – $200
A25: Contingency — Low Confidence % | B25: 0.2
A26: Contingency — Mid Confidence % | B26: 0.12 | F26: ⚠ Note: Fees vary by municipality. | G26: Always verify with AHJ.
A27: Contingency — High Confidence % | B27: 0.05
A29: MOBILIZATION & TRAVEL
A30: Mobilization — Fixed Cost per Job ($) | B30: =B11*B32 | C30: 1 hr/day × blended rate (auto)
A31: Travel / Per Diem per Crew Day ($) | B31: 0
A32: Estimated Crew Days on Job | B32: =CEILING(SUMMARY!B18/8,1) | C32: Auto: total labor hrs ÷ 8

Sheet CHANGES v3.1
A1: BARRETT PLUMBING INC. — COMMERCIAL ESTIMATOR v3.1 CHANGES
A2: Fixes to v3 found while building the create-budget-commercial skill. Rates and your inputs were not changed.
A4: # | B4: Where | C4: Problem in v3 | D4: Fix in v3.1
A5: 1 | B5: DEMO ESTIMATE E37 / G37 / H37 | C5: PIPE DEMO TOTAL used SUM(row 9:34), which also picked up the Cast Iron, PVC and Copper subtotal rows, so those demo hours and dollars were counted twice. | D5: Totals now add the four section subtotals (rows 13, 20, 28, 35).
A6: 2 | B6: DEMO ESTIMATE D42:D66, H42:H66 | C6: Cap/stub hours were added to the fixture demo cost (H) but not to the hours (D), so SUMMARY hours and crew-days missed them. | D6: D (TOTAL Demo Hrs) now includes cap/stub hours when the flag is Y; H = E. Dollar totals are unchanged.
A7: 3 | B7: FIXTURE SCHEDULE row 36 & new row 42; FIXTURE ESTIMATE B37 | C7: One "Grease Interceptor / Sand Separator" count fed both the indoor (6 h) and exterior (12 h) estimate rows, so one interceptor was charged 18 h. | D7: Row 36 is now Grease Interceptor (Indoor); new row 42 is Ext. Grease Interceptor / Sand Sep. (exterior / in-ground) and feeds FIXTURE ESTIMATE row 37.
A8: 4 | B8: LABOR TABLES new Table B2 (L15:Q23); PIPE ESTIMATE Sections 2-3 | C8: Water piping labor and material always used the Type L copper rows, whatever INPUT → Water Supply Pipe Material said. | D8: Table B2 picks Type L, Type K or PEX-B rates from INPUT E12 (PEX-B only has 1" and smaller; larger sizes fall back to Type L). Cold and hot sections read Table B2.
A9: 5 | B9: PIPE ESTIMATE new Section 6 (rows 56-62); SUMMARY rows 11 & 24; FIXTURE ESTIMATE B48:B50 | C9: Hot water recirculation LF on PIPE TAKEOFF was never priced: no labor, no material, no hangers. | D9: Section 6 prices recirc like the hot water section; SUMMARY shows it; recirc ceiling LF now counts toward hangers (6 ft spacing).
A10: 6 | B10: LABOR TABLES I49:I53; FIXTURE ESTIMATE C48:C52 | C10: Hanger hours were typed into FIXTURE ESTIMATE and disagreed with Table F (Table F had 1.0 / 1.5 / 0.20 / 0.15). | D10: Per Vance, kept the numbers estimates were using (0.25 / 0.75 / 1.25 / 0.10 per LF / 0.20). They now live in Table F and FIXTURE ESTIMATE links to it.
A11: 7 | B11: SUMMARY B33 and B29 | C11: The labor-cost subtotal skipped Plumbing Demolition, and sleeve labor cost only counted coordination hours (not install hours). | D11: B33 sums every line; sleeve labor cost = (install + coordination hrs) × blended rate, matching the hours line.
A12: 8 | B12: SETTINGS B32 | C12: Crew-days for mobilization left out CMU drop and sleeve hours (and now recirc), though the note says "total labor hrs ÷ 8". | D12: Now CEILING(SUMMARY!B18/8, 1): total labor hours ÷ 8, rounded up.
A13: 9 | B13: INPUT B15 | C13: The Building Type dropdown was attached to the section header (B14). | D13: Dropdown moved to B15; other entries are still allowed.
